(.venv) user@laptop vpcInterfaceend-cdk % cdk synth
jsii.errors.JavaScriptError: 
  @jsii/kernel.RuntimeError: Error: Cannot create a VPC Endpoint with no subnets
      at Kernel._Kernel_ensureSync (/private/var/folders/_g/160c7p7x79747n_90mt1chnx9w4r1h/T/tmplhsqdo5k/lib/program.js:10502:23)
      at Kernel.invoke (/private/var/folders/_g/160c7p7x79747n_90mt1chnx9w4r1h/T/tmplhsqdo5k/lib/program.js:9866:102)
      at KernelHost.processRequest (/private/var/folders/_g/160c7p7x79747n_90mt1chnx9w4r1h/T/tmplhsqdo5k/lib/program.js:11707:36)
      at KernelHost.run (/private/var/folders/_g/160c7p7x79747n_90mt1chnx9w4r1h/T/tmplhsqdo5k/lib/program.js:11667:22)
      at Immediate._onImmediate (/private/var/folders/_g/160c7p7x79747n_90mt1chnx9w4r1h/T/tmplhsqdo5k/lib/program.js:11668:46)
      at process.processImmediate (node:internal/timers:476:21)

The above exception was the direct cause of the following exception:

Traceback (most recent call last):
  File "/Users/user/project/vpcInterfaceend-cdk/app.py", line 10, in <module>
    VpcInterfaceendCdkStack(app, "VpcInterfaceendCdkStack",
  File "/Users/user/project/vpcInterfaceend-cdk/.venv/lib/python3.12/site-packages/jsii/_runtime.py", line 118, in __call__
    inst = super(JSIIMeta, cast(JSIIMeta, cls)).__call__(*args, **kwargs)
           ^^^^^^^^^^^^^^^^^^^^^^^^^^^^^^^^^^^^^^^^^^^^^^^^^^^^^^^^^^^^^^
  File "/Users/user/project/vpcInterfaceend-cdk/vpc_interfaceend_cdk/vpc_interfaceend_cdk_stack.py", line 39, in __init__
    vpc.add_interface_endpoint('SsmEndpoint', 
    ^^^^^^^^^^^^^^^^^^^^^^^^^^^^^^^^^^^^^^^^^
  File "/Users/user/project/vpcInterfaceend-cdk/.venv/lib/python3.12/site-packages/aws_cdk/aws_ec2/__init__.py", line 85736, in add_interface_endpoint
    return typing.cast("InterfaceVpcEndpoint", jsii.invoke(self, "addInterfaceEndpoint", [id, options]))
                                               ^^^^^^^^^^^^^^^^^^^^^^^^^^^^^^^^^^^^^^^^^^^^^^^^^^^^^^^^
  File "/Users/user/project/vpcInterfaceend-cdk/.venv/lib/python3.12/site-packages/jsii/_kernel/__init__.py", line 149, in wrapped
    return _recursize_dereference(kernel, fn(kernel, *args, **kwargs))
                                          ^^^^^^^^^^^^^^^^^^^^^^^^^^^
  File "/Users/user/project/vpcInterfaceend-cdk/.venv/lib/python3.12/site-packages/jsii/_kernel/__init__.py", line 399, in invoke
    response = self.provider.invoke(
               ^^^^^^^^^^^^^^^^^^^^^
  File "/Users/user/project/vpcInterfaceend-cdk/.venv/lib/python3.12/site-packages/jsii/_kernel/providers/process.py", line 380, in invoke
    return self._process.send(request, InvokeResponse)
           ^^^^^^^^^^^^^^^^^^^^^^^^^^^^^^^^^^^^^^^^^^^
  File "/Users/user/project/vpcInterfaceend-cdk/.venv/lib/python3.12/site-packages/jsii/_kernel/providers/process.py", line 342, in send
    raise RuntimeError(resp.error) from JavaScriptError(resp.stack)
RuntimeError: Error: Cannot create a VPC Endpoint with no subnets

Subprocess exited with error 1
